Workbook

Sheet Hypotheses
A1: Hub v2 — Previsionnel financier v1 — Hypotheses
A3: Hypothese | B3: Pessimiste | C3: Median | D3: Optimiste | E3: Commentaire
A5: Pricing Pro mensuel TTC (EUR) | B5: 29 | C5: 29 | D5: 29 | E5: Validé note pricing Hub IA 25 mai 2026
A6: Pricing Pro mensuel HT (EUR) | B6: =B5/1.2 -> 24.166667 | C6: =C5/1.2 -> 24.166667 | D6: =D5/1.2 -> 24.166667
A7: Pricing Equipe par siege HT (EUR/mois) | B7: =19/1.2 -> 15.833333 | C7: =19/1.2 -> 15.833333 | D7: =19/1.2 -> 15.833333
A9: ACQUISITION & CONVERSION
A10: Inscriptions Free annuelles (an 1) | B10: 1300 | C10: 5800 | D10: 16000
A11: Croissance inscriptions Free an 2 | B11: 0.5 | C11: 1 | D11: 1.5
A12: Croissance inscriptions Free an 3 | B12: 0.3 | C12: 0.6 | D12: 0.8
A13: Taux conversion Free -> Pro (% global) | B13: 0.01 | C13: 0.03 | D13: 0.05 | E13: Sources : benchmarks SaaS B2B/B2C 2026
A14: Churn mensuel Pro | B14: 0.07 | C14: 0.05 | D14: 0.03 | E14: B2B 3-5%/mois, B2C 5-7%/mois
A15: CAC moyen (EUR) | B15: 800 | C15: 400 | D15: 200 | E15: Réf. CAC B2B 2026 : 500-650 €
A17: TIER EQUIPE (active des Etape 5 / mois 4 post-T0)
A18: % Pro convertissant en Equipe | B18: 0.05 | C18: 0.1 | D18: 0.15
A19: Nb sieges moyen par compte Equipe | B19: 3 | C19: 4 | D19: 5
A21: COUTS UNITAIRES
A22: Cout LLM moyen par Pro/mois (EUR) | B22: 0.5 | C22: 0.4 | D22: 0.3 | E22: Mix Mistral Large 3 + Medium + Small
A23: Cout LLM moyen par Free/mois (EUR) | B23: 0.6 | C23: 0.5 | D23: 0.4
A24: % Free actifs consommant LLM | B24: 0.3 | C24: 0.3 | D24: 0.3
A25: Frais Stripe (% du CA Pro+Equipe) | B25: 0.022 | C25: 0.022 | D25: 0.022
A27: COUTS FIXES MENSUELS (EUR)
A28: Infrastructure amorcage (M1-M6) | B28: 100 | C28: 85 | D28: 70
A29: Infrastructure croissance (M7-M18) | B29: 350 | C29: 280 | D29: 200
A30: Infrastructure maturation (M19-M36) | B30: 1200 | C30: 900 | D30: 600
A31: Outils + marketing fixe | B31: 80 | C31: 100 | D31: 150
A33: CHARGES JURIDIQUES (EUR, ponctuelles)
A34: Consult avocat + audit RGPD (M1-M3) | B34: 3000 | C34: 2200 | D34: 1500
A35: CGV Pro + dossier IP (M6-M9) | B35: 4000 | C35: 3000 | D35: 2000
A36: Convention QFC + structure juridique (M9-M12) | B36: 4000 | C36: 3200 | D36: 2500
A37: DPA + ajustements (M15-M18) | B37: 1500 | C37: 1200 | D37: 800
A39: REDEVANCE QFC (piste B)
A40: Taux redevance sur CA HT | B40: 0.125 | C40: 0.125 | D40: 0.125 | E40: Point médian fourchette 10-15%
A41: Demarrage redevance (mois post-T0) | B41: 12 | C41: 9 | D41: 6

Sheet Pessimiste
A1: Hub v2 — P&L mensuel — Scenario Pessimiste
A3: Poste | B3: M0 | C3: M1 | D3: M2 | E3: M3 | F3: M4 | G3: M5 | H3: M6 | I3: M7 | J3: M8 | K3: M9 | L3: M10 | M3: M11 | N3: M12 | O3: M13 | P3: M14 | Q3: M15 | R3: M16 | S3: M17 | T3: M18 | U3: M19 | V3: M20 | W3: M21 | X3: M22 | Y3: M23 | Z3: M24 | AA3: M25 | AB3: M26 | AC3: M27 | AD3: M28 | AE3: M29 | AF3: M30 | AG3: M31 | AH3: M32 | AI3: M33 | AJ3: M34 | AK3: M35 | AL3: M36
A5: Inscriptions Free mensuelles | B5: 0 | C5: =Hypotheses!B10/12*0.5 -> 54.166667 | D5: =Hypotheses!B10/12*0.5 -> 54.166667 | E5: =Hypotheses!B10/12*0.5 -> 54.166667 | F5: =Hypotheses!B10/12*0.75 -> 81.25 | G5: =Hypotheses!B10/12*0.75 -> 81.25 | H5: =Hypotheses!B10/12*0.75 -> 81.25 | I5: =Hypotheses!B10/12 -> 108.33333 | J5: =Hypotheses!B10/12 -> 108.33333 | K5: =Hypotheses!B10/12 -> 108.33333 | L5: =Hypotheses!B10/12 -> 108.33333 | M5: =Hypotheses!B10/12 -> 108.33333 | N5: =Hypotheses!B10/12 -> 108.33333 | O5: =Hypotheses!B10/12*(1+Hypotheses!B11) -> 162.5 | P5: =Hypotheses!B10/12*(1+Hypotheses!B11) -> 162.5 | Q5: =Hypotheses!B10/12*(1+Hypotheses!B11) -> 162.5 | R5: =Hypotheses!B10/12*(1+Hypotheses!B11) -> 162.5 | S5: =Hypotheses!B10/12*(1+Hypotheses!B11) -> 162.5 | T5: =Hypotheses!B10/12*(1+Hypotheses!B11) -> 162.5 | U5: =Hypotheses!B10/12*(1+Hypotheses!B11) -> 162.5 | V5: =Hypotheses!B10/12*(1+Hypotheses!B11) -> 162.5 | W5: =Hypotheses!B10/12*(1+Hypotheses!B11) -> 162.5 | X5: =Hypotheses!B10/12*(1+Hypotheses!B11) -> 162.5 | Y5: =Hypotheses!B10/12*(1+Hypotheses!B11) -> 162.5 | Z5: =Hypotheses!B10/12*(1+Hypotheses!B11) -> 162.5 | AA5: =Hypotheses!B10/12*(1+Hypotheses!B11)*(1+Hypotheses!B12) -> 211.25 | AB5: =Hypotheses!B10/12*(1+Hypotheses!B11)*(1+Hypotheses!B12) -> 211.25 | AC5: =Hypotheses!B10/12*(1+Hypotheses!B11)*(1+Hypotheses!B12) -> 211.25 | AD5: =Hypotheses!B10/12*(1+Hypotheses!B11)*(1+Hypotheses!B12) -> 211.25 | AE5: =Hypotheses!B10/12*(1+Hypotheses!B11)*(1+Hypotheses!B12) -> 211.25 | AF5: =Hypotheses!B10/12*(1+Hypotheses!B11)*(1+Hypotheses!B12) -> 211.25 | AG5: =Hypotheses!B10/12*(1+Hypotheses!B11)*(1+Hypotheses!B12) -> 211.25 | AH5: =Hypotheses!B10/12*(1+Hypotheses!B11)*(1+Hypotheses!B12) -> 211.25 | AI5: =Hypotheses!B10/12*(1+Hypotheses!B11)*(1+Hypotheses!B12) -> 211.25 | AJ5: =Hypotheses!B10/12*(1+Hypotheses!B11)*(1+Hypotheses!B12) -> 211.25 | AK5: =Hypotheses!B10/12*(1+Hypotheses!B11)*(1+Hypotheses!B12) -> 211.25 | AL5: =Hypotheses!B10/12*(1+Hypotheses!B11)*(1+Hypotheses!B12) -> 211.25
A6: Inscriptions Free cumulees | B6: =B5 -> 0 | C6: =B6+C5 -> 54.166667 | D6: =C6+D5 -> 108.33333 | E6: =D6+E5 -> 162.5 | F6: =E6+F5 -> 243.75 | G6: =F6+G5 -> 325 | H6: =G6+H5 -> 406.25 | I6: =H6+I5 -> 514.58333 | J6: =I6+J5 -> 622.91667 | ... AL6: =AK6+AL5 -> 5541.25
A7: Nouveaux Pro mensuels | B7: =B5*Hypotheses!B13 -> 0 | C7: =C5*Hypotheses!B13 -> 0.54166667 | D7: =D5*Hypotheses!B13 -> 0.54166667 | E7: =E5*Hypotheses!B13 -> 0.54166667 | F7: =F5*Hypotheses!B13 -> 0.8125 | G7: =G5*Hypotheses!B13 -> 0.8125 | H7: =H5*Hypotheses!B13 -> 0.8125 | I7: =I5*Hypotheses!B13 -> 1.0833333 | J7: =J5*Hypotheses!B13 -> 1.0833333 | K7: =K5*Hypotheses!B13 -> 1.0833333 | L7: =L5*Hypotheses!B13 -> 1.0833333 | M7: =M5*Hypotheses!B13 -> 1.0833333 | N7: =N5*Hypotheses!B13 -> 1.0833333 | O7: =O5*Hypotheses!B13 -> 1.625 | P7: =P5*Hypotheses!B13 -> 1.625 | Q7: =Q5*Hypotheses!B13 -> 1.625 | R7: =R5*Hypotheses!B13 -> 1.625 | S7: =S5*Hypotheses!B13 -> 1.625 | T7: =T5*Hypotheses!B13 -> 1.625 | U7: =U5*Hypotheses!B13 -> 1.625 | V7: =V5*Hypotheses!B13 -> 1.625 | W7: =W5*Hypotheses!B13 -> 1.625 | X7: =X5*Hypotheses!B13 -> 1.625 | Y7: =Y5*Hypotheses!B13 -> 1.625 | Z7: =Z5*Hypotheses!B13 -> 1.625 | AA7: =AA5*Hypotheses!B13 -> 2.1125 | AB7: =AB5*Hypotheses!B13 -> 2.1125 | AC7: =AC5*Hypotheses!B13 -> 2.1125 | AD7: =AD5*Hypotheses!B13 -> 2.1125 | AE7: =AE5*Hypotheses!B13 -> 2.1125 | AF7: =AF5*Hypotheses!B13 -> 2.1125 | AG7: =AG5*Hypotheses!B13 -> 2.1125 | AH7: =AH5*Hypotheses!B13 -> 2.1125 | AI7: =AI5*Hypotheses!B13 -> 2.1125 | AJ7: =AJ5*Hypotheses!B13 -> 2.1125 | AK7: =AK5*Hypotheses!B13 -> 2.1125 | AL7: =AL5*Hypotheses!B13 -> 2.1125
A8: Pro actifs nets (avec churn) | B8: =B7 -> 0 | C8: =B8*(1-Hypotheses!B14)+C7 -> 0.54166667 | D8: =C8*(1-Hypotheses!B14)+D7 -> 1.0454167 | E8: =D8*(1-Hypotheses!B14)+E7 -> 1.5139042 | F8: =E8*(1-Hypotheses!B14)+F7 -> 2.2204309 | G8: =F8*(1-Hypotheses!B14)+G7 -> 2.8775007 | H8: =G8*(1-Hypotheses!B14)+H7 -> 3.4885757 | I8: =H8*(1-Hypotheses!B14)+I7 -> 4.3277087 | J8: =I8*(1-Hypotheses!B14)+J7 -> 5.1081024 | K8: =J8*(1-Hypotheses!B14)+K7 -> 5.8338686 | L8: =K8*(1-Hypotheses!B14)+L7 -> 6.5088311 | M8: =L8*(1-Hypotheses!B14)+M7 -> 7.1365463 | N8: =M8*(1-Hypotheses!B14)+N7 -> 7.7203214 | O8: =N8*(1-Hypotheses!B14)+O7 -> 8.8048989 | P8: =O8*(1-Hypotheses!B14)+P7 -> 9.813556 | Q8: =P8*(1-Hypotheses!B14)+Q7 -> 10.751607 | R8: =Q8*(1-Hypotheses!B14)+R7 -> 11.623995 | S8: =R8*(1-Hypotheses!B14)+S7 -> 12.435315 | T8: =S8*(1-Hypotheses!B14)+T7 -> 13.189843 | U8: =T8*(1-Hypotheses!B14)+U7 -> 13.891554 | V8: =U8*(1-Hypotheses!B14)+V7 -> 14.544145 | W8: =V8*(1-Hypotheses!B14)+W7 -> 15.151055 | X8: =W8*(1-Hypotheses!B14)+X7 -> 15.715481 | Y8: =X8*(1-Hypotheses!B14)+Y7 -> 16.240397 | Z8: =Y8*(1-Hypotheses!B14)+Z7 -> 16.72857 | AA8: =Z8*(1-Hypotheses!B14)+AA7 -> 17.67007 | AB8: =AA8*(1-Hypotheses!B14)+AB7 -> 18.545665 | AC8: =AB8*(1-Hypotheses!B14)+AC7 -> 19.359968 | AD8: =AC8*(1-Hypotheses!B14)+AD7 -> 20.117271 | AE8: =AD8*(1-Hypotheses!B14)+AE7 -> 20.821562 | AF8: =AE8*(1-Hypotheses!B14)+AF7 -> 21.476552 | AG8: =AF8*(1-Hypotheses!B14)+AG7 -> 22.085694 | AH8: =AG8*(1-Hypotheses!B14)+AH7 -> 22.652195 | AI8: =AH8*(1-Hypotheses!B14)+AI7 -> 23.179041 | AJ8: =AI8*(1-Hypotheses!B14)+AJ7 -> 23.669009 | AK8: =AJ8*(1-Hypotheses!B14)+AK7 -> 24.124678 | AL8: =AK8*(1-Hypotheses!B14)+AL7 -> 24.54845
A10: Pro actifs (arrondi) | B10: =ROUND(B8,0) -> 0 | C10: =ROUND(C8,0) -> 1 | D10: =ROUND(D8,0) -> 1 | E10: =ROUND(E8,0) -> 2 | F10: =ROUND(F8,0) -> 2 | G10: =ROUND(G8,0) -> 3 | H10: =ROUND(H8,0) -> 3 | I10: =ROUND(I8,0) -> 4 | ... AL10: =ROUND(AL8,0) -> 25
A12: Comptes Equipe | B12: 0 | C12: 0 | D12: 0 | E12: 0 | F12: =ROUND(F10*Hypotheses!B18,0) -> 0 | G12: =ROUND(G10*Hypotheses!B18,0) -> 0 | H12: =ROUND(H10*Hypotheses!B18,0) -> 0 | I12: =ROUND(I10*Hypotheses!B18,0) -> 0 | J12: =ROUND(J10*Hypotheses!B18,0) -> 0 | K12: =ROUND(K10*Hypotheses!B18,0) -> 0 | L12: =ROUND(L10*Hypotheses!B18,0) -> 0 | M12: =ROUND(M10*Hypotheses!B18,0) -> 0 | N12: =ROUND(N10*Hypotheses!B18,0) -> 0 | O12: =ROUND(O10*Hypotheses!B18,0) -> 0 | P12: =ROUND(P10*Hypotheses!B18,0) -> 1 | Q12: =ROUND(Q10*Hypotheses!B18,0) -> 1 | R12: =ROUND(R10*Hypotheses!B18,0) -> 1 | S12: =ROUND(S10*Hypotheses!B18,0) -> 1 | T12: =ROUND(T10*Hypotheses!B18,0) -> 1 | U12: =ROUND(U10*Hypotheses!B18,0) -> 1 | V12: =ROUND(V10*Hypotheses!B18,0) -> 1 | W12: =ROUND(W10*Hypotheses!B18,0) -> 1 | X12: =ROUND(X10*Hypotheses!B18,0) -> 1 | Y12: =ROUND(Y10*Hypotheses!B18,0) -> 1 | Z12: =ROUND(Z10*Hypotheses!B18,0) -> 1 | AA12: =ROUND(AA10*Hypotheses!B18,0) -> 1 | AB12: =ROUND(AB10*Hypotheses!B18,0) -> 1 | AC12: =ROUND(AC10*Hypotheses!B18,0) -> 1 | AD12: =ROUND(AD10*Hypotheses!B18,0) -> 1 | AE12: =ROUND(AE10*Hypotheses!B18,0) -> 1 | AF12: =ROUND(AF10*Hypotheses!B18,0) -> 1 | AG12: =ROUND(AG10*Hypotheses!B18,0) -> 1 | AH12: =ROUND(AH10*Hypotheses!B18,0) -> 1 | AI12: =ROUND(AI10*Hypotheses!B18,0) -> 1 | AJ12: =ROUND(AJ10*Hypotheses!B18,0) -> 1 | AK12: =ROUND(AK10*Hypotheses!B18,0) -> 1 | AL12: =ROUND(AL10*Hypotheses!B18,0) -> 1
A13: Sieges Equipe | B13: =B12*Hypotheses!B19 -> 0 | C13: =C12*Hypotheses!B19 -> 0 | D13: =D12*Hypotheses!B19 -> 0 | E13: =E12*Hypotheses!B19 -> 0 | F13: =F12*Hypotheses!B19 -> 0 | G13: =G12*Hypotheses!B19 -> 0 | H13: =H12*Hypotheses!B19 -> 0 | I13: =I12*Hypotheses!B19 -> 0 | J13: =J12*Hypotheses!B19 -> 0 | K13: =K12*Hypotheses!B19 -> 0 | L13: =L12*Hypotheses!B19 -> 0 | M13: =M12*Hypotheses!B19 -> 0 | N13: =N12*Hypotheses!B19 -> 0 | O13: =O12*Hypotheses!B19 -> 0 | P13: =P12*Hypotheses!B19 -> 3 | Q13: =Q12*Hypotheses!B19 -> 3 | R13: =R12*Hypotheses!B19 -> 3 | S13: =S12*Hypotheses!B19 -> 3 | T13: =T12*Hypotheses!B19 -> 3 | U13: =U12*Hypotheses!B19 -> 3 | V13: =V12*Hypotheses!B19 -> 3 | W13: =W12*Hypotheses!B19 -> 3 | X13: =X12*Hypotheses!B19 -> 3 | Y13: =Y12*Hypotheses!B19 -> 3 | Z13: =Z12*Hypotheses!B19 -> 3 | AA13: =AA12*Hypotheses!B19 -> 3 | AB13: =AB12*Hypotheses!B19 -> 3 | AC13: =AC12*Hypotheses!B19 -> 3 | AD13: =AD12*Hypotheses!B19 -> 3 | AE13: =AE12*Hypotheses!B19 -> 3 | AF13: =AF12*Hypotheses!B19 -> 3 | AG13: =AG12*Hypotheses!B19 -> 3 | AH13: =AH12*Hypotheses!B19 -> 3 | AI13: =AI12*Hypotheses!B19 -> 3 | AJ13: =AJ12*Hypotheses!B19 -> 3 | AK13: =AK12*Hypotheses!B19 -> 3 | AL13: =AL12*Hypotheses!B19 -> 3
A15: Revenu Pro mensuel HT (EUR) | B15: =B10*Hypotheses!B6 -> 0 | C15: =C10*Hypotheses!B6 -> 24.166667 | D15: =D10*Hypotheses!B6 -> 24.166667 | E15: =E10*Hypotheses!B6 -> 48.333333 | F15: =F10*Hypotheses!B6 -> 48.333333 | G15: =G10*Hypotheses!B6 -> 72.5 | H15: =H10*Hypotheses!B6 -> 72.5 | I15: =I10*Hypotheses!B6 -> 96.666667 | J15: =J10*Hypotheses!B6 -> 120.83333 | K15: =K10*Hypotheses!B6 -> 145 | L15: =L10*Hypotheses!B6 -> 169.16667 | M15: =M10*Hypotheses!B6 -> 169.16667 | N15: =N10*Hypotheses!B6 -> 193.33333 | O15: =O10*Hypotheses!B6 -> 217.5 | P15: =P10*Hypotheses!B6 -> 241.66667 | Q15: =Q10*Hypotheses!B6 -> 265.83333 | R15: =R10*Hypotheses!B6 -> 290 | S15: =S10*Hypotheses!B6 -> 290 | T15: =T10*Hypotheses!B6 -> 314.16667 | U15: =U10*Hypotheses!B6 -> 338.33333 | V15: =V10*Hypotheses!B6 -> 362.5 | W15: =W10*Hypotheses!B6 -> 362.5 | X15: =X10*Hypotheses!B6 -> 386.66667 | Y15: =Y10*Hypotheses!B6 -> 386.66667 | Z15: =Z10*Hypotheses!B6 -> 410.83333 | AA15: =AA10*Hypotheses!B6 -> 435 | AB15: =AB10*Hypotheses!B6 -> 459.16667 | AC15: =AC10*Hypotheses!B6 -> 459.16667 | AD15: =AD10*Hypotheses!B6 -> 483.33333 | AE15: =AE10*Hypotheses!B6 -> 507.5 | AF15: =AF10*Hypotheses!B6 -> 507.5 | AG15: =AG10*Hypotheses!B6 -> 531.66667 | AH15: =AH10*Hypotheses!B6 -> 555.83333 | AI15: =AI10*Hypotheses!B6 -> 555.83333 | AJ15: =AJ10*Hypotheses!B6 -> 580 | AK15: =AK10*Hypotheses!B6 -> 580 | AL15: =AL10*Hypotheses!B6 -> 604.16667
A16: Revenu Equipe mensuel HT (EUR) | B16: =B13*Hypotheses!B7 -> 0 | C16: =C13*Hypotheses!B7 -> 0 | D16: =D13*Hypotheses!B7 -> 0 | E16: =E13*Hypotheses!B7 -> 0 | F16: =F13*Hypotheses!B7 -> 0 | G16: =G13*Hypotheses!B7 -> 0 | H16: =H13*Hypotheses!B7 -> 0 | I16: =I13*Hypotheses!B7 -> 0 | J16: =J13*Hypotheses!B7 -> 0 | K16: =K13*Hypotheses!B7 -> 0 | L16: =L13*Hypotheses!B7 -> 0 | M16: =M13*Hypotheses!B7 -> 0 | N16: =N13*Hypotheses!B7 -> 0 | O16: =O13*Hypotheses!B7 -> 0 | P16: =P13*Hypotheses!B7 -> 47.5 | Q16: =Q13*Hypotheses!B7 -> 47.5 | R16: =R13*Hypotheses!B7 -> 47.5 | S16: =S13*Hypotheses!B7 -> 47.5 | T16: =T13*Hypotheses!B7 -> 47.5 | U16: =U13*Hypotheses!B7 -> 47.5 | V16: =V13*Hypotheses!B7 -> 47.5 | W16: =W13*Hypotheses!B7 -> 47.5 | X16: =X13*Hypotheses!B7 -> 47.5 | Y16: =Y13*Hypotheses!B7 -> 47.5 | Z16: =Z13*Hypotheses!B7 -> 47.5 | AA16: =AA13*Hypotheses!B7 -> 47.5 | AB16: =AB13*Hypotheses!B7 -> 47.5 | AC16: =AC13*Hypotheses!B7 -> 47.5 | AD16: =AD13*Hypotheses!B7 -> 47.5 | AE16: =AE13*Hypotheses!B7 -> 47.5 | AF16: =AF13*Hypotheses!B7 -> 47.5 | AG16: =AG13*Hypotheses!B7 -> 47.5 | AH16: =AH13*Hypotheses!B7 -> 47.5 | AI16: =AI13*Hypotheses!B7 -> 47.5 | AJ16: =AJ13*Hypotheses!B7 -> 47.5 | AK16: =AK13*Hypotheses!B7 -> 47.5 | AL16: =AL13*Hypotheses!B7 -> 47.5
A17: TOTAL REVENU MENSUEL HT (EUR) | B17: =B15+B16 -> 0 | C17: =C15+C16 -> 24.166667 | D17: =D15+D16 -> 24.166667 | E17: =E15+E16 -> 48.333333 | F17: =F15+F16 -> 48.333333 | G17: =G15+G16 -> 72.5 | H17: =H15+H16 -> 72.5 | I17: =I15+I16 -> 96.666667 | ... AL17: =AL15+AL16 -> 651.66667
A18: ARR HT (EUR) | B18: =B17*12 -> 0 | C18: =C17*12 -> 290 | D18: =D17*12 -> 290 | E18: =E17*12 -> 580 | F18: =F17*12 -> 580 | G18: =G17*12 -> 870 | H18: =H17*12 -> 870 | I18: =I17*12 -> 1160 | ... AL18: =AL17*12 -> 7820
A20: Cout LLM Pro mensuel (EUR) | B20: =-B10*Hypotheses!B22 -> 0 | C20: =-C10*Hypotheses!B22 -> -0.5 | D20: =-D10*Hypotheses!B22 -> -0.5 | E20: =-E10*Hypotheses!B22 -> -1 | F20: =-F10*Hypotheses!B22 -> -1 | G20: =-G10*Hypotheses!B22 -> -1.5 | H20: =-H10*Hypotheses!B22 -> -1.5 | I20: =-I10*Hypotheses!B22 -> -2 | J20: =-J10*Hypotheses!B22 -> -2.5 | K20: =-K10*Hypotheses!B22 -> -3 | L20: =-L10*Hypotheses!B22 -> -3.5 | M20: =-M10*Hypotheses!B22 -> -3.5 | N20: =-N10*Hypotheses!B22 -> -4 | O20: =-O10*Hypotheses!B22 -> -4.5 | P20: =-P10*Hypotheses!B22 -> -5 | Q20: =-Q10*Hypotheses!B22 -> -5.5 | R20: =-R10*Hypotheses!B22 -> -6 | S20: =-S10*Hypotheses!B22 -> -6 | T20: =-T10*Hypotheses!B22 -> -6.5 | U20: =-U10*Hypotheses!B22 -> -7 | V20: =-V10*Hypotheses!B22 -> -7.5 | W20: =-W10*Hypotheses!B22 -> -7.5 | X20: =-X10*Hypotheses!B22 -> -8 | Y20: =-Y10*Hypotheses!B22 -> -8 | Z20: =-Z10*Hypotheses!B22 -> -8.5 | AA20: =-AA10*Hypotheses!B22 -> -9 | AB20: =-AB10*Hypotheses!B22 -> -9.5 | AC20: =-AC10*Hypotheses!B22 -> -9.5 | AD20: =-AD10*Hypotheses!B22 -> -10 | AE20: =-AE10*Hypotheses!B22 -> -10.5 | AF20: =-AF10*Hypotheses!B22 -> -10.5 | AG20: =-AG10*Hypotheses!B22 -> -11 | AH20: =-AH10*Hypotheses!B22 -> -11.5 | AI20: =-AI10*Hypotheses!B22 -> -11.5 | AJ20: =-AJ10*Hypotheses!B22 -> -12 | AK20: =-AK10*Hypotheses!B22 -> -12 | AL20: =-AL10*Hypotheses!B22 -> -12.5
A21: Cout LLM Free mensuel (EUR) | B21: =-B6*Hypotheses!B24*Hypotheses!B23 -> 0 | C21: =-C6*Hypotheses!B24*Hypotheses!B23 -> -9.75 | D21: =-D6*Hypotheses!B24*Hypotheses!B23 -> -19.5 | E21: =-E6*Hypotheses!B24*Hypotheses!B23 -> -29.25 | F21: =-F6*Hypotheses!B24*Hypotheses!B23 -> -43.875 | G21: =-G6*Hypotheses!B24*Hypotheses!B23 -> -58.5 | H21: =-H6*Hypotheses!B24*Hypotheses!B23 -> -73.125 | I21: =-I6*Hypotheses!B24*Hypotheses!B23 -> -92.625 | J21: =-J6*Hypotheses!B24*Hypotheses!B23 -> -112.125 | K21: =-K6*Hypotheses!B24*Hypotheses!B23 -> -131.625 | L21: =-L6*Hypotheses!B24*Hypotheses!B23 -> -151.125 | M21: =-M6*Hypotheses!B24*Hypotheses!B23 -> -170.625 | N21: =-N6*Hypotheses!B24*Hypotheses!B23 -> -190.125 | O21: =-O6*Hypotheses!B24*Hypotheses!B23 -> -219.375 | P21: =-P6*Hypotheses!B24*Hypotheses!B23 -> -248.625 | Q21: =-Q6*Hypotheses!B24*Hypotheses!B23 -> -277.875 | R21: =-R6*Hypotheses!B24*Hypotheses!B23 -> -307.125 | S21: =-S6*Hypotheses!B24*Hypotheses!B23 -> -336.375 | T21: =-T6*Hypotheses!B24*Hypotheses!B23 -> -365.625 | U21: =-U6*Hypotheses!B24*Hypotheses!B23 -> -394.875 | V21: =-V6*Hypotheses!B24*Hypotheses!B23 -> -424.125 | W21: =-W6*Hypotheses!B24*Hypotheses!B23 -> -453.375 | X21: =-X6*Hypotheses!B24*Hypotheses!B23 -> -482.625 | Y21: =-Y6*Hypotheses!B24*Hypotheses!B23 -> -511.875 | Z21: =-Z6*Hypotheses!B24*Hypotheses!B23 -> -541.125 | AA21: =-AA6*Hypotheses!B24*Hypotheses!B23 -> -579.15 | AB21: =-AB6*Hypotheses!B24*Hypotheses!B23 -> -617.175 | AC21: =-AC6*Hypotheses!B24*Hypotheses!B23 -> -655.2 | AD21: =-AD6*Hypotheses!B24*Hypotheses!B23 -> -693.225 | AE21: =-AE6*Hypotheses!B24*Hypotheses!B23 -> -731.25 | AF21: =-AF6*Hypotheses!B24*Hypotheses!B23 -> -769.275 | AG21: =-AG6*Hypotheses!B24*Hypotheses!B23 -> -807.3 | AH21: =-AH6*Hypotheses!B24*Hypotheses!B23 -> -845.325 | AI21: =-AI6*Hypotheses!B24*Hypotheses!B23 -> -883.35 | AJ21: =-AJ6*Hypotheses!B24*Hypotheses!B23 -> -921.375 | AK21: =-AK6*Hypotheses!B24*Hypotheses!B23 -> -959.4 | AL21: =-AL6*Hypotheses!B24*Hypotheses!B23 -> -997.425
A22: Frais Stripe mensuel (EUR) | B22: =-B17*Hypotheses!B25 -> 0 | C22: =-C17*Hypotheses!B25 -> -0.53166667 | D22: =-D17*Hypotheses!B25 -> -0.53166667 | E22: =-E17*Hypotheses!B25 -> -1.0633333 | F22: =-F17*Hypotheses!B25 -> -1.0633333 | G22: =-G17*Hypotheses!B25 -> -1.595 | H22: =-H17*Hypotheses!B25 -> -1.595 | I22: =-I17*Hypotheses!B25 -> -2.1266667 | J22: =-J17*Hypotheses!B25 -> -2.6583333 | K22: =-K17*Hypotheses!B25 -> -3.19 | L22: =-L17*Hypotheses!B25 -> -3.7216667 | M22: =-M17*Hypotheses!B25 -> -3.7216667 | N22: =-N17*Hypotheses!B25 -> -4.2533333 | O22: =-O17*Hypotheses!B25 -> -4.785 | P22: =-P17*Hypotheses!B25 -> -6.3616667 | Q22: =-Q17*Hypotheses!B25 -> -6.8933333 | R22: =-R17*Hypotheses!B25 -> -7.425 | S22: =-S17*Hypotheses!B25 -> -7.425 | T22: =-T17*Hypotheses!B25 -> -7.9566667 | U22: =-U17*Hypotheses!B25 -> -8.4883333 | V22: =-V17*Hypotheses!B25 -> -9.02 | W22: =-W17*Hypotheses!B25 -> -9.02 | X22: =-X17*Hypotheses!B25 -> -9.5516667 | Y22: =-Y17*Hypotheses!B25 -> -9.5516667 | Z22: =-Z17*Hypotheses!B25 -> -10.083333 | AA22: =-AA17*Hypotheses!B25 -> -10.615 | AB22: =-AB17*Hypotheses!B25 -> -11.146667 | AC22: =-AC17*Hypotheses!B25 -> -11.146667 | AD22: =-AD17*Hypotheses!B25 -> -11.678333 | AE22: =-AE17*Hypotheses!B25 -> -12.21 | AF22: =-AF17*Hypotheses!B25 -> -12.21 | AG22: =-AG17*Hypotheses!B25 -> -12.741667 | AH22: =-AH17*Hypotheses!B25 -> -13.273333 | AI22: =-AI17*Hypotheses!B25 -> -13.273333 | AJ22: =-AJ17*Hypotheses!B25 -> -13.805 | AK22: =-AK17*Hypotheses!B25 -> -13.805 | AL22: =-AL17*Hypotheses!B25 -> -14.336667
A23: MARGE BRUTE MENSUELLE (EUR) | B23: =B17+B20+B21+B22 -> 0 | C23: =C17+C20+C21+C22 -> 13.385 | D23: =D17+D20+D21+D22 -> 3.635 | E23: =E17+E20+E21+E22 -> 17.02 | F23: =F17+F20+F21+F22 -> 2.395 | G23: =G17+G20+G21+G22 -> 10.905 | H23: =H17+H20+H21+H22 -> -3.72 | I23: =I17+I20+I21+I22 -> -0.085 | ... AL23: =AL17+AL20+AL21+AL22 -> -372.595
A25: Couts fixes mensuels (EUR) | B25: =-(Hypotheses!B28+Hypotheses!B31) -> -180 | C25: =-(Hypotheses!B28+Hypotheses!B31) -> -180 | D25: =-(Hypotheses!B28+Hypotheses!B31) -> -180 | E25: =-(Hypotheses!B28+Hypotheses!B31) -> -180 | F25: =-(Hypotheses!B28+Hypotheses!B31) -> -180 | G25: =-(Hypotheses!B28+Hypotheses!B31) -> -180 | H25: =-(Hypotheses!B28+Hypotheses!B31) -> -180 | I25: =-(Hypotheses!B29+Hypotheses!B31) -> -430 | J25: =-(Hypotheses!B29+Hypotheses!B31) -> -430 | K25: =-(Hypotheses!B29+Hypotheses!B31) -> -430 | L25: =-(Hypotheses!B29+Hypotheses!B31) -> -430 | M25: =-(Hypotheses!B29+Hypotheses!B31) -> -430 | N25: =-(Hypotheses!B29+Hypotheses!B31) -> -430 | O25: =-(Hypotheses!B29+Hypotheses!B31) -> -430 | P25: =-(Hypotheses!B29+Hypotheses!B31) -> -430 | Q25: =-(Hypotheses!B29+Hypotheses!B31) -> -430 | R25: =-(Hypotheses!B29+Hypotheses!B31) -> -430 | S25: =-(Hypotheses!B29+Hypotheses!B31) -> -430 | T25: =-(Hypotheses!B29+Hypotheses!B31) -> -430 | U25: =-(Hypotheses!B30+Hypotheses!B31) -> -1280 | V25: =-(Hypotheses!B30+Hypotheses!B31) -> -1280 | W25: =-(Hypotheses!B30+Hypotheses!B31) -> -1280 | X25: =-(Hypotheses!B30+Hypotheses!B31) -> -1280 | Y25: =-(Hypotheses!B30+Hypotheses!B31) -> -1280 | Z25: =-(Hypotheses!B30+Hypotheses!B31) -> -1280 | AA25: =-(Hypotheses!B30+Hypotheses!B31) -> -1280 | AB25: =-(Hypotheses!B30+Hypotheses!B31) -> -1280 | AC25: =-(Hypotheses!B30+Hypotheses!B31) -> -1280 | AD25: =-(Hypotheses!B30+Hypotheses!B31) -> -1280 | AE25: =-(Hypotheses!B30+Hypotheses!B31) -> -1280 | AF25: =-(Hypotheses!B30+Hypotheses!B31) -> -1280 | AG25: =-(Hypotheses!B30+Hypotheses!B31) -> -1280 | AH25: =-(Hypotheses!B30+Hypotheses!B31) -> -1280 | AI25: =-(Hypotheses!B30+Hypotheses!B31) -> -1280 | AJ25: =-(Hypotheses!B30+Hypotheses!B31) -> -1280 | AK25: =-(Hypotheses!B30+Hypotheses!B31) -> -1280 | AL25: =-(Hypotheses!B30+Hypotheses!B31) -> -1280
A26: Cout d'acquisition mensuel (EUR) | B26: =-B7*Hypotheses!B15 -> 0 | C26: =-C7*Hypotheses!B15 -> -433.33333 | D26: =-D7*Hypotheses!B15 -> -433.33333 | E26: =-E7*Hypotheses!B15 -> -433.33333 | F26: =-F7*Hypotheses!B15 -> -650 | G26: =-G7*Hypotheses!B15 -> -650 | H26: =-H7*Hypotheses!B15 -> -650 | I26: =-I7*Hypotheses!B15 -> -866.66667 | J26: =-J7*Hypotheses!B15 -> -866.66667 | K26: =-K7*Hypotheses!B15 -> -866.66667 | L26: =-L7*Hypotheses!B15 -> -866.66667 | M26: =-M7*Hypotheses!B15 -> -866.66667 | N26: =-N7*Hypotheses!B15 -> -866.66667 | O26: =-O7*Hypotheses!B15 -> -1300 | P26: =-P7*Hypotheses!B15 -> -1300 | Q26: =-Q7*Hypotheses!B15 -> -1300 | R26: =-R7*Hypotheses!B15 -> -1300 | S26: =-S7*Hypotheses!B15 -> -1300 | T26: =-T7*Hypotheses!B15 -> -1300 | U26: =-U7*Hypotheses!B15 -> -1300 | V26: =-V7*Hypotheses!B15 -> -1300 | W26: =-W7*Hypotheses!B15 -> -1300 | X26: =-X7*Hypotheses!B15 -> -1300 | Y26: =-Y7*Hypotheses!B15 -> -1300 | Z26: =-Z7*Hypotheses!B15 -> -1300 | AA26: =-AA7*Hypotheses!B15 -> -1690 | AB26: =-AB7*Hypotheses!B15 -> -1690 | AC26: =-AC7*Hypotheses!B15 -> -1690 | AD26: =-AD7*Hypotheses!B15 -> -1690 | AE26: =-AE7*Hypotheses!B15 -> -1690 | AF26: =-AF7*Hypotheses!B15 -> -1690 | AG26: =-AG7*Hypotheses!B15 -> -1690 | AH26: =-AH7*Hypotheses!B15 -> -1690 | AI26: =-AI7*Hypotheses!B15 -> -1690 | AJ26: =-AJ7*Hypotheses!B15 -> -1690 | AK26: =-AK7*Hypotheses!B15 -> -1690 | AL26: =-AL7*Hypotheses!B15 -> -1690
A27: Charges juridiques ponctuelles (EUR) | B27: 0 | C27: =-Hypotheses!B34/3 -> -1000 | D27: =-Hypotheses!B34/3 -> -1000 | E27: =-Hypotheses!B34/3 -> -1000 | F27: 0 | G27: 0 | H27: 0 | I27: =-Hypotheses!B35/3 -> -1333.3333 | J27: =-Hypotheses!B35/3 -> -1333.3333 | K27: =-Hypotheses!B35/3 -> -1333.3333 | L27: =-Hypotheses!B36/3 -> -1333.3333 | M27: =-Hypotheses!B36/3 -> -1333.3333 | N27: =-Hypotheses!B36/3 -> -1333.3333 | O27: 0 | P27: 0 | Q27: 0 | R27: =-Hypotheses!B37/3 -> -500 | S27: =-Hypotheses!B37/3 -> -500 | T27: =-Hypotheses!B37/3 -> -500 | U27: 0 | V27: 0 | W27: 0 | X27: 0 | Y27: 0 | Z27: 0 | AA27: 0 | AB27: 0 | AC27: 0 | AD27: 0 | AE27: 0 | AF27: 0 | AG27: 0 | AH27: 0 | AI27: 0 | AJ27: 0 | AK27: 0 | AL27: 0
A28: Redevance QFC (piste B) mensuelle (EUR) | B28: =IF(0>=Hypotheses!B41,-B17*Hypotheses!B40,0) -> 0 | C28: =IF(1>=Hypotheses!B41,-C17*Hypotheses!B40,0) -> 0 | D28: =IF(2>=Hypotheses!B41,-D17*Hypotheses!B40,0) -> 0 | E28: =IF(3>=Hypotheses!B41,-E17*Hypotheses!B40,0) -> 0 | F28: =IF(4>=Hypotheses!B41,-F17*Hypotheses!B40,0) -> 0 | G28: =IF(5>=Hypotheses!B41,-G17*Hypotheses!B40,0) -> 0 | H28: =IF(6>=Hypotheses!B41,-H17*Hypotheses!B40,0) -> 0 | I28: =IF(7>=Hypotheses!B41,-I17*Hypotheses!B40,0) -> 0 | J28: =IF(8>=Hypotheses!B41,-J17*Hypotheses!B40,0) -> 0 | K28: =IF(9>=Hypotheses!B41,-K17*Hypotheses!B40,0) -> 0 | L28: =IF(10>=Hypotheses!B41,-L17*Hypotheses!B40,0) -> 0 | M28: =IF(11>=Hypotheses!B41,-M17*Hypotheses!B40,0) -> 0 | N28: =IF(12>=Hypotheses!B41,-N17*Hypotheses!B40,0) -> -24.166667 | O28: =IF(13>=Hypotheses!B41,-O17*Hypotheses!B40,0) -> -27.1875 | P28: =IF(14>=Hypotheses!B41,-P17*Hypotheses!B40,0) -> -36.145833 | Q28: =IF(15>=Hypotheses!B41,-Q17*Hypotheses!B40,0) -> -39.166667 | R28: =IF(16>=Hypotheses!B41,-R17*Hypotheses!B40,0) -> -42.1875 | S28: =IF(17>=Hypotheses!B41,-S17*Hypotheses!B40,0) -> -42.1875 | T28: =IF(18>=Hypotheses!B41,-T17*Hypotheses!B40,0) -> -45.208333 | U28: =IF(19>=Hypotheses!B41,-U17*Hypotheses!B40,0) -> -48.229167 | V28: =IF(20>=Hypotheses!B41,-V17*Hypotheses!B40,0) -> -51.25 | W28: =IF(21>=Hypotheses!B41,-W17*Hypotheses!B40,0) -> -51.25 | X28: =IF(22>=Hypotheses!B41,-X17*Hypotheses!B40,0) -> -54.270833 | Y28: =IF(23>=Hypotheses!B41,-Y17*Hypotheses!B40,0) -> -54.270833 | Z28: =IF(24>=Hypotheses!B41,-Z17*Hypotheses!B40,0) -> -57.291667 | AA28: =IF(25>=Hypotheses!B41,-AA17*Hypotheses!B40,0) -> -60.3125 | AB28: =IF(26>=Hypotheses!B41,-AB17*Hypotheses!B40,0) -> -63.333333 | AC28: =IF(27>=Hypotheses!B41,-AC17*Hypotheses!B40,0) -> -63.333333 | AD28: =IF(28>=Hypotheses!B41,-AD17*Hypotheses!B40,0) -> -66.354167 | AE28: =IF(29>=Hypotheses!B41,-AE17*Hypotheses!B40,0) -> -69.375 | AF28: =IF(30>=Hypotheses!B41,-AF17*Hypotheses!B40,0) -> -69.375 | AG28: =IF(31>=Hypotheses!B41,-AG17*Hypotheses!B40,0) -> -72.395833 | AH28: =IF(32>=Hypotheses!B41,-AH17*Hypotheses!B40,0) -> -75.416667 | AI28: =IF(33>=Hypotheses!B41,-AI17*Hypotheses!B40,0) -> -75.416667 | AJ28: =IF(34>=Hypotheses!B41,-AJ17*Hypotheses!B40,0) -> -78.4375 | AK28: =IF(35>=Hypotheses!B41,-AK17*Hypotheses!B40,0) -> -78.4375 | AL28: =IF(36>=Hypotheses!B41,-AL17*Hypotheses!B40,0) -> -81.458333
A30: RESULTAT OPERATIONNEL MENSUEL (EUR) | B30: =B23+B25+B26+B27+B28 -> -180 | C30: =C23+C25+C26+C27+C28 -> -1599.9483 | D30: =D23+D25+D26+D27+D28 -> -1609.6983 | E30: =E23+E25+E26+E27+E28 -> -1596.3133 | F30: =F23+F25+F26+F27+F28 -> -827.605 | G30: =G23+G25+G26+G27+G28 -> -819.095 | H30: =H23+H25+H26+H27+H28 -> -833.72 | I30: =I23+I25+I26+I27+I28 -> -2630.085 | ... AL30: =AL23+AL25+AL26+AL27+AL28 -> -3424.0533
A32: CASH FLOW CUMULE (EUR) | B32: =B30 -> -180 | C32: =B32+C30 -> -1779.9483 | D32: =C32+D30 -> -3389.6467 | E32: =D32+E30 -> -4985.96 | F32: =E32+F30 -> -5813.565 | G32: =F32+G30 -> -6632.66 | H32: =G32+H30 -> -7466.38 | I32: =H32+I30 -> -10096.465 | J32: =I32+J30 -> -12722.915 | ... AL32: =AK32+AL30 -> -90925.513

Sheet Median
A1: Hub v2 — P&L mensuel — Scenario Median
A3: Poste | B3: M0 | C3: M1 | D3: M2 | E3: M3 | F3: M4 | G3: M5 | H3: M6 | I3: M7 | J3: M8 | K3: M9 | L3: M10 | M3: M11 | N3: M12 | O3: M13 | P3: M14 | Q3: M15 | R3: M16 | S3: M17 | T3: M18 | U3: M19 | V3: M20 | W3: M21 | X3: M22 | Y3: M23 | Z3: M24 | AA3: M25 | AB3: M26 | AC3: M27 | AD3: M28 | AE3: M29 | AF3: M30 | AG3: M31 | AH3: M32 | AI3: M33 | AJ3: M34 | AK3: M35 | AL3: M36
A5: Inscriptions Free mensuelles | B5: 0 | C5: =Hypotheses!C10/12*0.5 -> 241.66667 | D5: =Hypotheses!C10/12*0.5 -> 241.66667 | E5: =Hypotheses!C10/12*0.5 -> 241.66667 | F5: =Hypotheses!C10/12*0.75 -> 362.5 | G5: =Hypotheses!C10/12*0.75 -> 362.5 | H5: =Hypotheses!C10/12*0.75 -> 362.5 | I5: =Hypotheses!C10/12 -> 483.33333 | J5: =Hypotheses!C10/12 -> 483.33333 | K5: =Hypotheses!C10/12 -> 483.33333 | L5: =Hypotheses!C10/12 -> 483.33333 | M5: =Hypotheses!C10/12 -> 483.33333 | N5: =Hypotheses!C10/12 -> 483.33333 | O5: =Hypotheses!C10/12*(1+Hypotheses!C11) -> 966.66667 | P5: =Hypotheses!C10/12*(1+Hypotheses!C11) -> 966.66667 | Q5: =Hypotheses!C10/12*(1+Hypotheses!C11) -> 966.66667 | R5: =Hypotheses!C10/12*(1+Hypotheses!C11) -> 966.66667 | S5: =Hypotheses!C10/12*(1+Hypotheses!C11) -> 966.66667 | T5: =Hypotheses!C10/12*(1+Hypotheses!C11) -> 966.66667 | U5: =Hypotheses!C10/12*(1+Hypotheses!C11) -> 966.66667 | V5: =Hypotheses!C10/12*(1+Hypotheses!C11) -> 966.66667 | W5: =Hypotheses!C10/12*(1+Hypotheses!C11) -> 966.66667 | X5: =Hypotheses!C10/12*(1+Hypotheses!C11) -> 966.66667 | Y5: =Hypotheses!C10/12*(1+Hypotheses!C11) -> 966.66667 | Z5: =Hypotheses!C10/12*(1+Hypotheses!C11) -> 966.66667 | AA5: =Hypotheses!C10/12*(1+Hypotheses!C11)*(1+Hypotheses!C12) -> 1546.6667 | AB5: =Hypotheses!C10/12*(1+Hypotheses!C11)*(1+Hypotheses!C12) -> 1546.6667 | AC5: =Hypotheses!C10/12*(1+Hypotheses!C11)*(1+Hypotheses!C12) -> 1546.6667 | AD5: =Hypotheses!C10/12*(1+Hypotheses!C11)*(1+Hypotheses!C12) -> 1546.6667 | AE5: =Hypotheses!C10/12*(1+Hypotheses!C11)*(1+Hypotheses!C12) -> 1546.6667 | AF5: =Hypotheses!C10/12*(1+Hypotheses!C11)*(1+Hypotheses!C12) -> 1546.6667 | AG5: =Hypotheses!C10/12*(1+Hypotheses!C11)*(1+Hypotheses!C12) -> 1546.6667 | AH5: =Hypotheses!C10/12*(1+Hypotheses!C11)*(1+Hypotheses!C12) -> 1546.6667 | AI5: =Hypotheses!C10/12*(1+Hypotheses!C11)*(1+Hypotheses!C12) -> 1546.6667 | AJ5: =Hypotheses!C10/12*(1+Hypotheses!C11)*(1+Hypotheses!C12) -> 1546.6667 | AK5: =Hypotheses!C10/12*(1+Hypotheses!C11)*(1+Hypotheses!C12) -> 1546.6667 | AL5: =Hypotheses!C10/12*(1+Hypotheses!C11)*(1+Hypotheses!C12) -> 1546.6667
A6: Inscriptions Free cumulees | B6: =B5 -> 0 | C6: =B6+C5 -> 241.66667 | D6: =C6+D5 -> 483.33333 | E6: =D6+E5 -> 725 | F6: =E6+F5 -> 1087.5 | G6: =F6+G5 -> 1450 | H6: =G6+H5 -> 1812.5 | I6: =H6+I5 -> 2295.8333 | J6: =I6+J5 -> 2779.1667 | ... AL6: =AK6+AL5 -> 34872.5
A7: Nouveaux Pro mensuels | B7: =B5*Hypotheses!C13 -> 0 | C7: =C5*Hypotheses!C13 -> 7.25 | D7: =D5*Hypotheses!C13 -> 7.25 | E7: =E5*Hypotheses!C13 -> 7.25 | F7: =F5*Hypotheses!C13 -> 10.875 | G7: =G5*Hypotheses!C13 -> 10.875 | H7: =H5*Hypotheses!C13 -> 10.875 | I7: =I5*Hypotheses!C13 -> 14.5 | J7: =J5*Hypotheses!C13 -> 14.5 | K7: =K5*Hypotheses!C13 -> 14.5 | L7: =L5*Hypotheses!C13 -> 14.5 | M7: =M5*Hypotheses!C13 -> 14.5 | N7: =N5*Hypotheses!C13 -> 14.5 | O7: =O5*Hypotheses!C13 -> 29 | P7: =P5*Hypotheses!C13 -> 29 | Q7: =Q5*Hypotheses!C13 -> 29 | R7: =R5*Hypotheses!C13 -> 29 | S7: =S5*Hypotheses!C13 -> 29 | T7: =T5*Hypotheses!C13 -> 29 | U7: =U5*Hypotheses!C13 -> 29 | V7: =V5*Hypotheses!C13 -> 29 | W7: =W5*Hypotheses!C13 -> 29 | X7: =X5*Hypotheses!C13 -> 29 | Y7: =Y5*Hypotheses!C13 -> 29 | Z7: =Z5*Hypotheses!C13 -> 29 | AA7: =AA5*Hypotheses!C13 -> 46.4 | AB7: =AB5*Hypotheses!C13 -> 46.4 | AC7: =AC5*Hypotheses!C13 -> 46.4 | AD7: =AD5*Hypotheses!C13 -> 46.4 | AE7: =AE5*Hypotheses!C13 -> 46.4 | AF7: =AF5*Hypotheses!C13 -> 46.4 | AG7: =AG5*Hypotheses!C13 -> 46.4 | AH7: =AH5*Hypotheses!C13 -> 46.4 | AI7: =AI5*Hypotheses!C13 -> 46.4 | AJ7: =AJ5*Hypotheses!C13 -> 46.4 | AK7: =AK5*Hypotheses!C13 -> 46.4 | AL7: =AL5*Hypotheses!C13 -> 46.4
A8: Pro actifs nets (avec churn) | B8: =B7 -> 0 | C8: =B8*(1-Hypotheses!C14)+C7 -> 7.25 | D8: =C8*(1-Hypotheses!C14)+D7 -> 14.1375 | E8: =D8*(1-Hypotheses!C14)+E7 -> 20.680625 | F8: =E8*(1-Hypotheses!C14)+F7 -> 30.521594 | G8: =F8*(1-Hypotheses!C14)+G7 -> 39.870514 | H8: =G8*(1-Hypotheses!C14)+H7 -> 48.751988 | I8: =H8*(1-Hypotheses!C14)+I7 -> 60.814389 | J8: =I8*(1-Hypotheses!C14)+J7 -> 72.273669 | K8: =J8*(1-Hypotheses!C14)+K7 -> 83.159986 | L8: =K8*(1-Hypotheses!C14)+L7 -> 93.501987 | M8: =L8*(1-Hypotheses!C14)+M7 -> 103.32689 | N8: =M8*(1-Hypotheses!C14)+N7 -> 112.66054 | O8: =N8*(1-Hypotheses!C14)+O7 -> 136.02752 | P8: =O8*(1-Hypotheses!C14)+P7 -> 158.22614 | Q8: =P8*(1-Hypotheses!C14)+Q7 -> 179.31483 | R8: =Q8*(1-Hypotheses!C14)+R7 -> 199.34909 | S8: =R8*(1-Hypotheses!C14)+S7 -> 218.38164 | T8: =S8*(1-Hypotheses!C14)+T7 -> 236.46256 | U8: =T8*(1-Hypotheses!C14)+U7 -> 253.63943 | V8: =U8*(1-Hypotheses!C14)+V7 -> 269.95746 | W8: =V8*(1-Hypotheses!C14)+W7 -> 285.45958 | X8: =W8*(1-Hypotheses!C14)+X7 -> 300.1866 | Y8: =X8*(1-Hypotheses!C14)+Y7 -> 314.17727 | Z8: =Y8*(1-Hypotheses!C14)+Z7 -> 327.46841 | AA8: =Z8*(1-Hypotheses!C14)+AA7 -> 357.49499 | AB8: =AA8*(1-Hypotheses!C14)+AB7 -> 386.02024 | AC8: =AB8*(1-Hypotheses!C14)+AC7 -> 413.11923 | AD8: =AC8*(1-Hypotheses!C14)+AD7 -> 438.86327 | AE8: =AD8*(1-Hypotheses!C14)+AE7 -> 463.3201 | AF8: =AE8*(1-Hypotheses!C14)+AF7 -> 486.5541 | AG8: =AF8*(1-Hypotheses!C14)+AG7 -> 508.62639 | AH8: =AG8*(1-Hypotheses!C14)+AH7 -> 529.59507 | AI8: =AH8*(1-Hypotheses!C14)+AI7 -> 549.51532 | AJ8: =AI8*(1-Hypotheses!C14)+AJ7 -> 568.43955 | AK8: =AJ8*(1-Hypotheses!C14)+AK7 -> 586.41758 | AL8: =AK8*(1-Hypotheses!C14)+AL7 -> 603.4967
A10: Pro actifs (arrondi) | B10: =ROUND(B8,0) -> 0 | C10: =ROUND(C8,0) -> 7 | D10: =ROUND(D8,0) -> 14 | E10: =ROUND(E8,0) -> 21 | F10: =ROUND(F8,0) -> 31 | G10: =ROUND(G8,0) -> 40 | H10: =ROUND(H8,0) -> 49 | I10: =ROUND(I8,0) -> 61 | ... AL10: =ROUND(AL8,0) -> 603
A12: Comptes Equipe | B12: 0 | C12: 0 | D12: 0 | E12: 0 | F12: =ROUND(F10*Hypotheses!C18,0) -> 3 | G12: =ROUND(G10*Hypotheses!C18,0) -> 4 | H12: =ROUND(H10*Hypotheses!C18,0) -> 5 | I12: =ROUND(I10*Hypotheses!C18,0) -> 6 | J12: =ROUND(J10*Hypotheses!C18,0) -> 7 | K12: =ROUND(K10*Hypotheses!C18,0) -> 8 | L12: =ROUND(L10*Hypotheses!C18,0) -> 9 | M12: =ROUND(M10*Hypotheses!C18,0) -> 10 | N12: =ROUND(N10*Hypotheses!C18,0) -> 11 | O12: =ROUND(O10*Hypotheses!C18,0) -> 14 | P12: =ROUND(P10*Hypotheses!C18,0) -> 16 | Q12: =ROUND(Q10*Hypotheses!C18,0) -> 18 | R12: =ROUND(R10*Hypotheses!C18,0) -> 20 | S12: =ROUND(S10*Hypotheses!C18,0) -> 22 | T12: =ROUND(T10*Hypotheses!C18,0) -> 24 | U12: =ROUND(U10*Hypotheses!C18,0) -> 25 | V12: =ROUND(V10*Hypotheses!C18,0) -> 27 | W12: =ROUND(W10*Hypotheses!C18,0) -> 29 | X12: =ROUND(X10*Hypotheses!C18,0) -> 30 | Y12: =ROUND(Y10*Hypotheses!C18,0) -> 31 | Z12: =ROUND(Z10*Hypotheses!C18,0) -> 33 | AA12: =ROUND(AA10*Hypotheses!C18,0) -> 36 | AB12: =ROUND(AB10*Hypotheses!C18,0) -> 39 | AC12: =ROUND(AC10*Hypotheses!C18,0) -> 41 | AD12: =ROUND(AD10*Hypotheses!C18,0) -> 44 | AE12: =ROUND(AE10*Hypotheses!C18,0) -> 46 | AF12: =ROUND(AF10*Hypotheses!C18,0) -> 49 | AG12: =ROUND(AG10*Hypotheses!C18,0) -> 51 | AH12: =ROUND(AH10*Hypotheses!C18,0) -> 53 | AI12: =ROUND(AI10*Hypotheses!C18,0) -> 55 | AJ12: =ROUND(AJ10*Hypotheses!C18,0) -> 57 | AK12: =ROUND(AK10*Hypotheses!C18,0) -> 59 | AL12: =ROUND(AL10*Hypotheses!C18,0) -> 60
A13: Sieges Equipe | B13: =B12*Hypotheses!C19 -> 0 | C13: =C12*Hypotheses!C19 -> 0 | D13: =D12*Hypotheses!C19 -> 0 | E13: =E12*Hypotheses!C19 -> 0 | F13: =F12*Hypotheses!C19 -> 12 | G13: =G12*Hypotheses!C19 -> 16 | H13: =H12*Hypotheses!C19 -> 20 | I13: =I12*Hypotheses!C19 -> 24 | J13: =J12*Hypotheses!C19 -> 28 | K13: =K12*Hypotheses!C19 -> 32 | L13: =L12*Hypotheses!C19 -> 36 | M13: =M12*Hypotheses!C19 -> 40 | N13: =N12*Hypotheses!C19 -> 44 | O13: =O12*Hypotheses!C19 -> 56 | P13: =P12*Hypotheses!C19 -> 64 | Q13: =Q12*Hypotheses!C19 -> 72 | R13: =R12*Hypotheses!C19 -> 80 | S13: =S12*Hypotheses!C19 -> 88 | T13: =T12*Hypotheses!C19 -> 96 | U13: =U12*Hypotheses!C19 -> 100 | V13: =V12*Hypotheses!C19 -> 108 | W13: =W12*Hypotheses!C19 -> 116 | X13: =X12*Hypotheses!C19 -> 120 | Y13: =Y12*Hypotheses!C19 -> 124 | Z13: =Z12*Hypotheses!C19 -> 132 | AA13: =AA12*Hypotheses!C19 -> 144 | AB13: =AB12*Hypotheses!C19 -> 156 | AC13: =AC12*Hypotheses!C19 -> 164 | AD13: =AD12*Hypotheses!C19 -> 176 | AE13: =AE12*Hypotheses!C19 -> 184 | AF13: =AF12*Hypotheses!C19 -> 196 | AG13: =AG12*Hypotheses!C19 -> 204 | AH13: =AH12*Hypotheses!C19 -> 212 | AI13: =AI12*Hypotheses!C19 -> 220 | AJ13: =AJ12*Hypotheses!C19 -> 228 | AK13: =AK12*Hypotheses!C19 -> 236 | AL13: =AL12*Hypotheses!C19 -> 240
A15: Revenu Pro mensuel HT (EUR) | B15: =B10*Hypotheses!C6 -> 0 | C15: =C10*Hypotheses!C6 -> 169.16667 | D15: =D10*Hypotheses!C6 -> 338.33333 | E15: =E10*Hypotheses!C6 -> 507.5 | F15: =F10*Hypotheses!C6 -> 749.16667 | G15: =G10*Hypotheses!C6 -> 966.66667 | H15: =H10*Hypotheses!C6 -> 1184.1667 | I15: =I10*Hypotheses!C6 -> 1474.1667 | J15: =J10*Hypotheses!C6 -> 1740 | K15: =K10*Hypotheses!C6 -> 2005.8333 | L15: =L10*Hypotheses!C6 -> 2271.6667 | M15: =M10*Hypotheses!C6 -> 2489.1667 | N15: =N10*Hypotheses!C6 -> 2730.8333 | O15: =O10*Hypotheses!C6 -> 3286.6667 | P15: =P10*Hypotheses!C6 -> 3818.3333 | Q15: =Q10*Hypotheses!C6 -> 4325.8333 | R15: =R10*Hypotheses!C6 -> 4809.1667 | S15: =S10*Hypotheses!C6 -> 5268.3333 | T15: =T10*Hypotheses!C6 -> 5703.3333 | U15: =U10*Hypotheses!C6 -> 6138.3333 | V15: =V10*Hypotheses!C6 -> 6525 | W15: =W10*Hypotheses!C6 -> 6887.5 | X15: =X10*Hypotheses!C6 -> 7250 | Y15: =Y10*Hypotheses!C6 -> 7588.3333 | Z15: =Z10*Hypotheses!C6 -> 7902.5 | AA15: =AA10*Hypotheses!C6 -> 8627.5 | AB15: =AB10*Hypotheses!C6 -> 9328.3333 | AC15: =AC10*Hypotheses!C6 -> 9980.8333 | AD15: =AD10*Hypotheses!C6 -> 10609.167 | AE15: =AE10*Hypotheses!C6 -> 11189.167 | AF15: =AF10*Hypotheses!C6 -> 11769.167 | AG15: =AG10*Hypotheses!C6 -> 12300.833 | AH15: =AH10*Hypotheses!C6 -> 12808.333 | AI15: =AI10*Hypotheses!C6 -> 13291.667 | AJ15: =AJ10*Hypotheses!C6 -> 13726.667 | AK15: =AK10*Hypotheses!C6 -> 14161.667 | AL15: =AL10*Hypotheses!C6 -> 14572.5
A16: Revenu Equipe mensuel HT (EUR) | B16: =B13*Hypotheses!C7 -> 0 | C16: =C13*Hypotheses!C7 -> 0 | D16: =D13*Hypotheses!C7 -> 0 | E16: =E13*Hypotheses!C7 -> 0 | F16: =F13*Hypotheses!C7 -> 190 | G16: =G13*Hypotheses!C7 -> 253.33333 | H16: =H13*Hypotheses!C7 -> 316.66667 | I16: =I13*Hypotheses!C7 -> 380 | J16: =J13*Hypotheses!C7 -> 443.33333 | K16: =K13*Hypotheses!C7 -> 506.66667 | L16: =L13*Hypotheses!C7 -> 570 | M16: =M13*Hypotheses!C7 -> 633.33333 | N16: =N13*Hypotheses!C7 -> 696.66667 | O16: =O13*Hypotheses!C7 -> 886.66667 | P16: =P13*Hypotheses!C7 -> 1013.3333 | Q16: =Q13*Hypotheses!C7 -> 1140 | R16: =R13*Hypotheses!C7 -> 1266.6667 | S16: =S13*Hypotheses!C7 -> 1393.3333 | T16: =T13*Hypotheses!C7 -> 1520 | U16: =U13*Hypotheses!C7 -> 1583.3333 | V16: =V13*Hypotheses!C7 -> 1710 | W16: =W13*Hypotheses!C7 -> 1836.6667 | X16: =X13*Hypotheses!C7 -> 1900 | Y16: =Y13*Hypotheses!C7 -> 1963.3333 | Z16: =Z13*Hypotheses!C7 -> 2090 | AA16: =AA13*Hypotheses!C7 -> 2280 | AB16: =AB13*Hypotheses!C7 -> 2470 | AC16: =AC13*Hypotheses!C7 -> 2596.6667 | AD16: =AD13*Hypotheses!C7 -> 2786.6667 | AE16: =AE13*Hypotheses!C7 -> 2913.3333 | AF16: =AF13*Hypotheses!C7 -> 3103.3333 | AG16: =AG13*Hypotheses!C7 -> 3230 | AH16: =AH13*Hypotheses!C7 -> 3356.6667 | AI16: =AI13*Hypotheses!C7 -> 3483.3333 | AJ16: =AJ13*Hypotheses!C7 -> 3610 | AK16: =AK13*Hypotheses!C7 -> 3736.6667 | AL16: =AL13*Hypotheses!C7 -> 3800
A17: TOTAL REVENU MENSUEL HT (EUR) | B17: =B15+B16 -> 0 | C17: =C15+C16 -> 169.16667 | D17: =D15+D16 -> 338.33333 | E17: =E15+E16 -> 507.5 | F17: =F15+F16 -> 939.16667 | G17: =G15+G16 -> 1220 | H17: =H15+H16 -> 1500.8333 | I17: =I15+I16 -> 1854.1667 | ... AL17: =AL15+AL16 -> 18372.5
A18: ARR HT (EUR) | B18: =B17*12 -> 0 | C18: =C17*12 -> 2030 | D18: =D17*12 -> 4060 | E18: =E17*12 -> 6090 | F18: =F17*12 -> 11270 | G18: =G17*12 -> 14640 | H18: =H17*12 -> 18010 | I18: =I17*12 -> 22250 | ... AL18: =AL17*12 -> 220470
A20: Cout LLM Pro mensuel (EUR) | B20: =-B10*Hypotheses!C22 -> 0 | C20: =-C10*Hypotheses!C22 -> -2.8 | D20: =-D10*Hypotheses!C22 -> -5.6 | E20: =-E10*Hypotheses!C22 -> -8.4 | F20: =-F10*Hypotheses!C22 -> -12.4 | G20: =-G10*Hypotheses!C22 -> -16 | H20: =-H10*Hypotheses!C22 -> -19.6 | I20: =-I10*Hypotheses!C22 -> -24.4 | J20: =-J10*Hypotheses!C22 -> -28.8 | K20: =-K10*Hypotheses!C22 -> -33.2 | L20: =-L10*Hypotheses!C22 -> -37.6 | M20: =-M10*Hypotheses!C22 -> -41.2 | N20: =-N10*Hypotheses!C22 -> -45.2 | O20: =-O10*Hypotheses!C22 -> -54.4 | P20: =-P10*Hypotheses!C22 -> -63.2 | Q20: =-Q10*Hypotheses!C22 -> -71.6 | R20: =-R10*Hypotheses!C22 -> -79.6 | S20: =-S10*Hypotheses!C22 -> -87.2 | T20: =-T10*Hypotheses!C22 -> -94.4 | U20: =-U10*Hypotheses!C22 -> -101.6 | V20: =-V10*Hypotheses!C22 -> -108 | W20: =-W10*Hypotheses!C22 -> -114 | X20: =-X10*Hypotheses!C22 -> -120 | Y20: =-Y10*Hypotheses!C22 -> -125.6 | Z20: =-Z10*Hypotheses!C22 -> -130.8 | AA20: =-AA10*Hypotheses!C22 -> -142.8 | AB20: =-AB10*Hypotheses!C22 -> -154.4 | AC20: =-AC10*Hypotheses!C22 -> -165.2 | AD20: =-AD10*Hypotheses!C22 -> -175.6 | AE20: =-AE10*Hypotheses!C22 -> -185.2 | AF20: =-AF10*Hypotheses!C22 -> -194.8 | AG20: =-AG10*Hypotheses!C22 -> -203.6 | AH20: =-AH10*Hypotheses!C22 -> -212 | AI20: =-AI10*Hypotheses!C22 -> -220 | AJ20: =-AJ10*Hypotheses!C22 -> -227.2 | AK20: =-AK10*Hypotheses!C22 -> -234.4 | AL20: =-AL10*Hypotheses!C22 -> -241.2
A21: Cout LLM Free mensuel (EUR) | B21: =-B6*Hypotheses!C24*Hypotheses!C23 -> 0 | C21: =-C6*Hypotheses!C24*Hypotheses!C23 -> -36.25 | D21: =-D6*Hypotheses!C24*Hypotheses!C23 -> -72.5 | E21: =-E6*Hypotheses!C24*Hypotheses!C23 -> -108.75 | F21: =-F6*Hypotheses!C24*Hypotheses!C23 -> -163.125 | G21: =-G6*Hypotheses!C24*Hypotheses!C23 -> -217.5 | H21: =-H6*Hypotheses!C24*Hypotheses!C23 -> -271.875 | I21: =-I6*Hypotheses!C24*Hypotheses!C23 -> -344.375 | J21: =-J6*Hypotheses!C24*Hypotheses!C23 -> -416.875 | K21: =-K6*Hypotheses!C24*Hypotheses!C23 -> -489.375 | L21: =-L6*Hypotheses!C24*Hypotheses!C23 -> -561.875 | M21: =-M6*Hypotheses!C24*Hypotheses!C23 -> -634.375 | N21: =-N6*Hypotheses!C24*Hypotheses!C23 -> -706.875 | O21: =-O6*Hypotheses!C24*Hypotheses!C23 -> -851.875 | P21: =-P6*Hypotheses!C24*Hypotheses!C23 -> -996.875 | Q21: =-Q6*Hypotheses!C24*Hypotheses!C23 -> -1141.875 | R21: =-R6*Hypotheses!C24*Hypotheses!C23 -> -1286.875 | S21: =-S6*Hypotheses!C24*Hypotheses!C23 -> -1431.875 | T21: =-T6*Hypotheses!C24*Hypotheses!C23 -> -1576.875 | U21: =-U6*Hypotheses!C24*Hypotheses!C23 -> -1721.875 | V21: =-V6*Hypotheses!C24*Hypotheses!C23 -> -1866.875 | W21: =-W6*Hypotheses!C24*Hypotheses!C23 -> -2011.875 | X21: =-X6*Hypotheses!C24*Hypotheses!C23 -> -2156.875 | Y21: =-Y6*Hypotheses!C24*Hypotheses!C23 -> -2301.875 | Z21: =-Z6*Hypotheses!C24*Hypotheses!C23 -> -2446.875 | AA21: =-AA6*Hypotheses!C24*Hypotheses!C23 -> -2678.875 | AB21: =-AB6*Hypotheses!C24*Hypotheses!C23 -> -2910.875 | AC21: =-AC6*Hypotheses!C24*Hypotheses!C23 -> -3142.875 | AD21: =-AD6*Hypotheses!C24*Hypotheses!C23 -> -3374.875 | AE21: =-AE6*Hypotheses!C24*Hypotheses!C23 -> -3606.875 | AF21: =-AF6*Hypotheses!C24*Hypotheses!C23 -> -3838.875 | AG21: =-AG6*Hypotheses!C24*Hypotheses!C23 -> -4070.875 | AH21: =-AH6*Hypotheses!C24*Hypotheses!C23 -> -4302.875 | AI21: =-AI6*Hypotheses!C24*Hypotheses!C23 -> -4534.875 | AJ21: =-AJ6*Hypotheses!C24*Hypotheses!C23 -> -4766.875 | AK21: =-AK6*Hypotheses!C24*Hypotheses!C23 -> -4998.875 | AL21: =-AL6*Hypotheses!C24*Hypotheses!C23 -> -5230.875
A22: Frais Stripe mensuel (EUR) | B22: =-B17*Hypotheses!C25 -> 0 | C22: =-C17*Hypotheses!C25 -> -3.7216667 | D22: =-D17*Hypotheses!C25 -> -7.4433333 | E22: =-E17*Hypotheses!C25 -> -11.165 | F22: =-F17*Hypotheses!C25 -> -20.661667 | G22: =-G17*Hypotheses!C25 -> -26.84 | H22: =-H17*Hypotheses!C25 -> -33.018333 | I22: =-I17*Hypotheses!C25 -> -40.791667 | J22: =-J17*Hypotheses!C25 -> -48.033333 | K22: =-K17*Hypotheses!C25 -> -55.275 | L22: =-L17*Hypotheses!C25 -> -62.516667 | M22: =-M17*Hypotheses!C25 -> -68.695 | N22: =-N17*Hypotheses!C25 -> -75.405 | O22: =-O17*Hypotheses!C25 -> -91.813333 | P22: =-P17*Hypotheses!C25 -> -106.29667 | Q22: =-Q17*Hypotheses!C25 -> -120.24833 | R22: =-R17*Hypotheses!C25 -> -133.66833 | S22: =-S17*Hypotheses!C25 -> -146.55667 | T22: =-T17*Hypotheses!C25 -> -158.91333 | U22: =-U17*Hypotheses!C25 -> -169.87667 | V22: =-V17*Hypotheses!C25 -> -181.17 | W22: =-W17*Hypotheses!C25 -> -191.93167 | X22: =-X17*Hypotheses!C25 -> -201.3 | Y22: =-Y17*Hypotheses!C25 -> -210.13667 | Z22: =-Z17*Hypotheses!C25 -> -219.835 | AA22: =-AA17*Hypotheses!C25 -> -239.965 | AB22: =-AB17*Hypotheses!C25 -> -259.56333 | AC22: =-AC17*Hypotheses!C25 -> -276.705 | AD22: =-AD17*Hypotheses!C25 -> -294.70833 | AE22: =-AE17*Hypotheses!C25 -> -310.255 | AF22: =-AF17*Hypotheses!C25 -> -327.195 | AG22: =-AG17*Hypotheses!C25 -> -341.67833 | AH22: =-AH17*Hypotheses!C25 -> -355.63 | AI22: =-AI17*Hypotheses!C25 -> -369.05 | AJ22: =-AJ17*Hypotheses!C25 -> -381.40667 | AK22: =-AK17*Hypotheses!C25 -> -393.76333 | AL22: =-AL17*Hypotheses!C25 -> -404.195
A23: MARGE BRUTE MENSUELLE (EUR) | B23: =B17+B20+B21+B22 -> 0 | C23: =C17+C20+C21+C22 -> 126.395 | D23: =D17+D20+D21+D22 -> 252.79 | E23: =E17+E20+E21+E22 -> 379.185 | F23: =F17+F20+F21+F22 -> 742.98 | G23: =G17+G20+G21+G22 -> 959.66 | H23: =H17+H20+H21+H22 -> 1176.34 | I23: =I17+I20+I21+I22 -> 1444.6 | ... AL23: =AL17+AL20+AL21+AL22 -> 12496.23
A25: Couts fixes mensuels (EUR) | B25: =-(Hypotheses!C28+Hypotheses!C31) -> -185 | C25: =-(Hypotheses!C28+Hypotheses!C31) -> -185 | D25: =-(Hypotheses!C28+Hypotheses!C31) -> -185 | E25: =-(Hypotheses!C28+Hypotheses!C31) -> -185 | F25: =-(Hypotheses!C28+Hypotheses!C31) -> -185 | G25: =-(Hypotheses!C28+Hypotheses!C31) -> -185 | H25: =-(Hypotheses!C28+Hypotheses!C31) -> -185 | I25: =-(Hypotheses!C29+Hypotheses!C31) -> -380 | J25: =-(Hypotheses!C29+Hypotheses!C31) -> -380 | K25: =-(Hypotheses!C29+Hypotheses!C31) -> -380 | L25: =-(Hypotheses!C29+Hypotheses!C31) -> -380 | M25: =-(Hypotheses!C29+Hypotheses!C31) -> -380 | N25: =-(Hypotheses!C29+Hypotheses!C31) -> -380 | O25: =-(Hypotheses!C29+Hypotheses!C31) -> -380 | P25: =-(Hypotheses!C29+Hypotheses!C31) -> -380 | Q25: =-(Hypotheses!C29+Hypotheses!C31) -> -380 | R25: =-(Hypotheses!C29+Hypotheses!C31) -> -380 | S25: =-(Hypotheses!C29+Hypotheses!C31) -> -380 | T25: =-(Hypotheses!C29+Hypotheses!C31) -> -380 | U25: =-(Hypotheses!C30+Hypotheses!C31) -> -1000 | V25: =-(Hypotheses!C30+Hypotheses!C31) -> -1000 | W25: =-(Hypotheses!C30+Hypotheses!C31) -> -1000 | X25: =-(Hypotheses!C30+Hypotheses!C31) -> -1000 | Y25: =-(Hypotheses!C30+Hypotheses!C31) -> -1000 | Z25: =-(Hypotheses!C30+Hypotheses!C31) -> -1000 | AA25: =-(Hypotheses!C30+Hypotheses!C31) -> -1000 | AB25: =-(Hypotheses!C30+Hypotheses!C31) -> -1000 | AC25: =-(Hypotheses!C30+Hypotheses!C31) -> -1000 | AD25: =-(Hypotheses!C30+Hypotheses!C31) -> -1000 | AE25: =-(Hypotheses!C30+Hypotheses!C31) -> -1000 | AF25: =-(Hypotheses!C30+Hypotheses!C31) -> -1000 | AG25: =-(Hypotheses!C30+Hypotheses!C31) -> -1000 | AH25: =-(Hypotheses!C30+Hypotheses!C31) -> -1000 | AI25: =-(Hypotheses!C30+Hypotheses!C31) -> -1000 | AJ25: =-(Hypotheses!C30+Hypotheses!C31) -> -1000 | AK25: =-(Hypotheses!C30+Hypotheses!C31) -> -1000 | AL25: =-(Hypotheses!C30+Hypotheses!C31) -> -1000
A26: Cout d'acquisition mensuel (EUR) | B26: =-B7*Hypotheses!C15 -> 0 | C26: =-C7*Hypotheses!C15 -> -2900 | D26: =-D7*Hypotheses!C15 -> -2900 | E26: =-E7*Hypotheses!C15 -> -2900 | F26: =-F7*Hypotheses!C15 -> -4350 | G26: =-G7*Hypotheses!C15 -> -4350 | H26: =-H7*Hypotheses!C15 -> -4350 | I26: =-I7*Hypotheses!C15 -> -5800 | J26: =-J7*Hypotheses!C15 -> -5800 | K26: =-K7*Hypotheses!C15 -> -5800 | L26: =-L7*Hypotheses!C15 -> -5800 | M26: =-M7*Hypotheses!C15 -> -5800 | N26: =-N7*Hypotheses!C15 -> -5800 | O26: =-O7*Hypotheses!C15 -> -11600 | P26: =-P7*Hypotheses!C15 -> -11600 | Q26: =-Q7*Hypotheses!C15 -> -11600 | R26: =-R7*Hypotheses!C15 -> -11600 | S26: =-S7*Hypotheses!C15 -> -11600 | T26: =-T7*Hypotheses!C15 -> -11600 | U26: =-U7*Hypotheses!C15 -> -11600 | V26: =-V7*Hypotheses!C15 -> -11600 | W26: =-W7*Hypotheses!C15 -> -11600 | X26: =-X7*Hypotheses!C15 -> -11600 | Y26: =-Y7*Hypotheses!C15 -> -11600 | Z26: =-Z7*Hypotheses!C15 -> -11600 | AA26: =-AA7*Hypotheses!C15 -> -18560 | AB26: =-AB7*Hypotheses!C15 -> -18560 | AC26: =-AC7*Hypotheses!C15 -> -18560 | AD26: =-AD7*Hypotheses!C15 -> -18560 | AE26: =-AE7*Hypotheses!C15 -> -18560 | AF26: =-AF7*Hypotheses!C15 -> -18560 | AG26: =-AG7*Hypotheses!C15 -> -18560 | AH26: =-AH7*Hypotheses!C15 -> -18560 | AI26: =-AI7*Hypotheses!C15 -> -18560 | AJ26: =-AJ7*Hypotheses!C15 -> -18560 | AK26: =-AK7*Hypotheses!C15 -> -18560 | AL26: =-AL7*Hypotheses!C15 -> -18560
A27: Charges juridiques ponctuelles (EUR) | B27: 0 | C27: =-Hypotheses!C34/3 -> -733.33333 | D27: =-Hypotheses!C34/3 -> -733.33333 | E27: =-Hypotheses!C34/3 -> -733.33333 | F27: 0 | G27: 0 | H27: 0 | I27: =-Hypotheses!C35/3 -> -1000 | J27: =-Hypotheses!C35/3 -> -1000 | K27: =-Hypotheses!C35/3 -> -1000 | L27: =-Hypotheses!C36/3 -> -1066.6667 | M27: =-Hypotheses!C36/3 -> -1066.6667 | N27: =-Hypotheses!C36/3 -> -1066.6667 | O27: 0 | P27: 0 | Q27: 0 | R27: =-Hypotheses!C37/3 -> -400 | S27: =-Hypotheses!C37/3 -> -400 | T27: =-Hypotheses!C37/3 -> -400 | U27: 0 | V27: 0 | W27: 0 | X27: 0 | Y27: 0 | Z27: 0 | AA27: 0 | AB27: 0 | AC27: 0 | AD27: 0 | AE27: 0 | AF27: 0 | AG27: 0 | AH27: 0 | AI27: 0 | AJ27: 0 | AK27: 0 | AL27: 0
A28: Redevance QFC (piste B) mensuelle (EUR) | B28: =IF(0>=Hypotheses!C41,-B17*Hypotheses!C40,0) -> 0 | C28: =IF(1>=Hypotheses!C41,-C17*Hypotheses!C40,0) -> 0 | D28: =IF(2>=Hypotheses!C41,-D17*Hypotheses!C40,0) -> 0 | E28: =IF(3>=Hypotheses!C41,-E17*Hypotheses!C40,0) -> 0 | F28: =IF(4>=Hypotheses!C41,-F17*Hypotheses!C40,0) -> 0 | G28: =IF(5>=Hypotheses!C41,-G17*Hypotheses!C40,0) -> 0 | H28: =IF(6>=Hypotheses!C41,-H17*Hypotheses!C40,0) -> 0 | I28: =IF(7>=Hypotheses!C41,-I17*Hypotheses!C40,0) -> 0 | J28: =IF(8>=Hypotheses!C41,-J17*Hypotheses!C40,0) -> 0 | K28: =IF(9>=Hypotheses!C41,-K17*Hypotheses!C40,0) -> -314.0625 | L28: =IF(10>=Hypotheses!C41,-L17*Hypotheses!C40,0) -> -355.20833 | M28: =IF(11>=Hypotheses!C41,-M17*Hypotheses!C40,0) -> -390.3125 | N28: =IF(12>=Hypotheses!C41,-N17*Hypotheses!C40,0) -> -428.4375 | O28: =IF(13>=Hypotheses!C41,-O17*Hypotheses!C40,0) -> -521.66667 | P28: =IF(14>=Hypotheses!C41,-P17*Hypotheses!C40,0) -> -603.95833 | Q28: =IF(15>=Hypotheses!C41,-Q17*Hypotheses!C40,0) -> -683.22917 | R28: =IF(16>=Hypotheses!C41,-R17*Hypotheses!C40,0) -> -759.47917 | S28: =IF(17>=Hypotheses!C41,-S17*Hypotheses!C40,0) -> -832.70833 | T28: =IF(18>=Hypotheses!C41,-T17*Hypotheses!C40,0) -> -902.91667 | U28: =IF(19>=Hypotheses!C41,-U17*Hypotheses!C40,0) -> -965.20833 | V28: =IF(20>=Hypotheses!C41,-V17*Hypotheses!C40,0) -> -1029.375 | W28: =IF(21>=Hypotheses!C41,-W17*Hypotheses!C40,0) -> -1090.5208 | X28: =IF(22>=Hypotheses!C41,-X17*Hypotheses!C40,0) -> -1143.75 | Y28: =IF(23>=Hypotheses!C41,-Y17*Hypotheses!C40,0) -> -1193.9583 | Z28: =IF(24>=Hypotheses!C41,-Z17*Hypotheses!C40,0) -> -1249.0625 | AA28: =IF(25>=Hypotheses!C41,-AA17*Hypotheses!C40,0) -> -1363.4375 | AB28: =IF(26>=Hypotheses!C41,-AB17*Hypotheses!C40,0) -> -1474.7917 | AC28: =IF(27>=Hypotheses!C41,-AC17*Hypotheses!C40,0) -> -1572.1875 | AD28: =IF(28>=Hypotheses!C41,-AD17*Hypotheses!C40,0) -> -1674.4792 | AE28: =IF(29>=Hypotheses!C41,-AE17*Hypotheses!C40,0) -> -1762.8125 | AF28: =IF(30>=Hypotheses!C41,-AF17*Hypotheses!C40,0) -> -1859.0625 | AG28: =IF(31>=Hypotheses!C41,-AG17*Hypotheses!C40,0) -> -1941.3542 | AH28: =IF(32>=Hypotheses!C41,-AH17*Hypotheses!C40,0) -> -2020.625 | AI28: =IF(33>=Hypotheses!C41,-AI17*Hypotheses!C40,0) -> -2096.875 | AJ28: =IF(34>=Hypotheses!C41,-AJ17*Hypotheses!C40,0) -> -2167.0833 | AK28: =IF(35>=Hypotheses!C41,-AK17*Hypotheses!C40,0) -> -2237.2917 | AL28: =IF(36>=Hypotheses!C41,-AL17*Hypotheses!C40,0) -> -2296.5625
A30: RESULTAT OPERATIONNEL MENSUEL (EUR) | B30: =B23+B25+B26+B27+B28 -> -185 | C30: =C23+C25+C26+C27+C28 -> -3691.9383 | D30: =D23+D25+D26+D27+D28 -> -3565.5433 | E30: =E23+E25+E26+E27+E28 -> -3439.1483 | F30: =F23+F25+F26+F27+F28 -> -3792.02 | G30: =G23+G25+G26+G27+G28 -> -3575.34 | H30: =H23+H25+H26+H27+H28 -> -3358.66 | I30: =I23+I25+I26+I27+I28 -> -5735.4 | ... AL30: =AL23+AL25+AL26+AL27+AL28 -> -9360.3325
A32: CASH FLOW CUMULE (EUR) | B32: =B30 -> -185 | C32: =B32+C30 -> -3876.9383 | D32: =C32+D30 -> -7442.4817 | E32: =D32+E30 -> -10881.63 | F32: =E32+F30 -> -14673.65 | G32: =F32+G30 -> -18248.99 | H32: =G32+H30 -> -21607.65 | I32: =H32+I30 -> -27343.05 | J32: =I32+J30 -> -32833.425 | ... AL32: =AK32+AL30 -> -280095.76

Sheet Optimiste
A1: Hub v2 — P&L mensuel — Scenario Optimiste
A3: Poste | B3: M0 | C3: M1 | D3: M2 | E3: M3 | F3: M4 | G3: M5 | H3: M6 | I3: M7 | J3: M8 | K3: M9 | L3: M10 | M3: M11 | N3: M12 | O3: M13 | P3: M14 | Q3: M15 | R3: M16 | S3: M17 | T3: M18 | U3: M19 | V3: M20 | W3: M21 | X3: M22 | Y3: M23 | Z3: M24 | AA3: M25 | AB3: M26 | AC3: M27 | AD3: M28 | AE3: M29 | AF3: M30 | AG3: M31 | AH3: M32 | AI3: M33 | AJ3: M34 | AK3: M35 | AL3: M36
A5: Inscriptions Free mensuelles | B5: 0 | C5: =Hypotheses!D10/12*0.5 -> 666.66667 | D5: =Hypotheses!D10/12*0.5 -> 666.66667 | E5: =Hypotheses!D10/12*0.5 -> 666.66667 | F5: =Hypotheses!D10/12*0.75 -> 1000 | G5: =Hypotheses!D10/12*0.75 -> 1000 | H5: =Hypotheses!D10/12*0.75 -> 1000 | I5: =Hypotheses!D10/12 -> 1333.3333 | J5: =Hypotheses!D10/12 -> 1333.3333 | K5: =Hypotheses!D10/12 -> 1333.3333 | L5: =Hypotheses!D10/12 -> 1333.3333 | M5: =Hypotheses!D10/12 -> 1333.3333 | N5: =Hypotheses!D10/12 -> 1333.3333 | O5: =Hypotheses!D10/12*(1+Hypotheses!D11) -> 3333.3333 | P5: =Hypotheses!D10/12*(1+Hypotheses!D11) -> 3333.3333 | Q5: =Hypotheses!D10/12*(1+Hypotheses!D11) -> 3333.3333 | R5: =Hypotheses!D10/12*(1+Hypotheses!D11) -> 3333.3333 | S5: =Hypotheses!D10/12*(1+Hypotheses!D11) -> 3333.3333 | T5: =Hypotheses!D10/12*(1+Hypotheses!D11) -> 3333.3333 | U5: =Hypotheses!D10/12*(1+Hypotheses!D11) -> 3333.3333 | V5: =Hypotheses!D10/12*(1+Hypotheses!D11) -> 3333.3333 | W5: =Hypotheses!D10/12*(1+Hypotheses!D11) -> 3333.3333 | X5: =Hypotheses!D10/12*(1+Hypotheses!D11) -> 3333.3333 | Y5: =Hypotheses!D10/12*(1+Hypotheses!D11) -> 3333.3333 | Z5: =Hypotheses!D10/12*(1+Hypotheses!D11) -> 3333.3333 | AA5: =Hypotheses!D10/12*(1+Hypotheses!D11)*(1+Hypotheses!D12) -> 6000 | AB5: =Hypotheses!D10/12*(1+Hypotheses!D11)*(1+Hypotheses!D12) -> 6000 | AC5: =Hypotheses!D10/12*(1+Hypotheses!D11)*(1+Hypotheses!D12) -> 6000 | AD5: =Hypotheses!D10/12*(1+Hypotheses!D11)*(1+Hypotheses!D12) -> 6000 | AE5: =Hypotheses!D10/12*(1+Hypotheses!D11)*(1+Hypotheses!D12) -> 6000 | AF5: =Hypotheses!D10/12*(1+Hypotheses!D11)*(1+Hypotheses!D12) -> 6000 | AG5: =Hypotheses!D10/12*(1+Hypotheses!D11)*(1+Hypotheses!D12) -> 6000 | AH5: =Hypotheses!D10/12*(1+Hypotheses!D11)*(1+Hypotheses!D12) -> 6000 | AI5: =Hypotheses!D10/12*(1+Hypotheses!D11)*(1+Hypotheses!D12) -> 6000 | AJ5: =Hypotheses!D10/12*(1+Hypotheses!D11)*(1+Hypotheses!D12) -> 6000 | AK5: =Hypotheses!D10/12*(1+Hypotheses!D11)*(1+Hypotheses!D12) -> 6000 | AL5: =Hypotheses!D10/12*(1+Hypotheses!D11)*(1+Hypotheses!D12) -> 6000
A6: Inscriptions Free cumulees | B6: =B5 -> 0 | C6: =B6+C5 -> 666.66667 | D6: =C6+D5 -> 1333.3333 | E6: =D6+E5 -> 2000 | F6: =E6+F5 -> 3000 | G6: =F6+G5 -> 4000 | H6: =G6+H5 -> 5000 | I6: =H6+I5 -> 6333.3333 | J6: =I6+J5 -> 7666.6667 | ... AL6: =AK6+AL5 -> 125000
A7: Nouveaux Pro mensuels | B7: =B5*Hypotheses!D13 -> 0 | C7: =C5*Hypotheses!D13 -> 33.333333 | D7: =D5*Hypotheses!D13 -> 33.333333 | E7: =E5*Hypotheses!D13 -> 33.333333 | F7: =F5*Hypotheses!D13 -> 50 | G7: =G5*Hypotheses!D13 -> 50 | H7: =H5*Hypotheses!D13 -> 50 | I7: =I5*Hypotheses!D13 -> 66.666667 | J7: =J5*Hypotheses!D13 -> 66.666667 | K7: =K5*Hypotheses!D13 -> 66.666667 | L7: =L5*Hypotheses!D13 -> 66.666667 | M7: =M5*Hypotheses!D13 -> 66.666667 | N7: =N5*Hypotheses!D13 -> 66.666667 | O7: =O5*Hypotheses!D13 -> 166.66667 | P7: =P5*Hypotheses!D13 -> 166.66667 | Q7: =Q5*Hypotheses!D13 -> 166.66667 | R7: =R5*Hypotheses!D13 -> 166.66667 | S7: =S5*Hypotheses!D13 -> 166.66667 | T7: =T5*Hypotheses!D13 -> 166.66667 | U7: =U5*Hypotheses!D13 -> 166.66667 | V7: =V5*Hypotheses!D13 -> 166.66667 | W7: =W5*Hypotheses!D13 -> 166.66667 | X7: =X5*Hypotheses!D13 -> 166.66667 | Y7: =Y5*Hypotheses!D13 -> 166.66667 | Z7: =Z5*Hypotheses!D13 -> 166.66667 | AA7: =AA5*Hypotheses!D13 -> 300 | AB7: =AB5*Hypotheses!D13 -> 300 | AC7: =AC5*Hypotheses!D13 -> 300 | AD7: =AD5*Hypotheses!D13 -> 300 | AE7: =AE5*Hypotheses!D13 -> 300 | AF7: =AF5*Hypotheses!D13 -> 300 | AG7: =AG5*Hypotheses!D13 -> 300 | AH7: =AH5*Hypotheses!D13 -> 300 | AI7: =AI5*Hypotheses!D13 -> 300 | AJ7: =AJ5*Hypotheses!D13 -> 300 | AK7: =AK5*Hypotheses!D13 -> 300 | AL7: =AL5*Hypotheses!D13 -> 300
A8: Pro actifs nets (avec churn) | B8: =B7 -> 0 | C8: =B8*(1-Hypotheses!D14)+C7 -> 33.333333 | D8: =C8*(1-Hypotheses!D14)+D7 -> 65.666667 | E8: =D8*(1-Hypotheses!D14)+E7 -> 97.03 | F8: =E8*(1-Hypotheses!D14)+F7 -> 144.1191 | G8: =F8*(1-Hypotheses!D14)+G7 -> 189.79553 | H8: =G8*(1-Hypotheses!D14)+H7 -> 234.10166 | I8: =H8*(1-Hypotheses!D14)+I7 -> 293.74528 | J8: =I8*(1-Hypotheses!D14)+J7 -> 351.59959 | K8: =J8*(1-Hypotheses!D14)+K7 -> 407.71827 | L8: =K8*(1-Hypotheses!D14)+L7 -> 462.15338 | M8: =L8*(1-Hypotheses!D14)+M7 -> 514.95545 | N8: =M8*(1-Hypotheses!D14)+N7 -> 566.17345 | O8: =N8*(1-Hypotheses!D14)+O7 -> 715.85492 | P8: =O8*(1-Hypotheses!D14)+P7 -> 861.04593 | Q8: =P8*(1-Hypotheses!D14)+Q7 -> 1001.8812 | R8: =Q8*(1-Hypotheses!D14)+R7 -> 1138.4915 | S8: =R8*(1-Hypotheses!D14)+S7 -> 1271.0034 | T8: =S8*(1-Hypotheses!D14)+T7 -> 1399.5399 | U8: =T8*(1-Hypotheses!D14)+U7 -> 1524.2204 | V8: =U8*(1-Hypotheses!D14)+V7 -> 1645.1605 | W8: =V8*(1-Hypotheses!D14)+W7 -> 1762.4723 | X8: =W8*(1-Hypotheses!D14)+X7 -> 1876.2648 | Y8: =X8*(1-Hypotheses!D14)+Y7 -> 1986.6435 | Z8: =Y8*(1-Hypotheses!D14)+Z7 -> 2093.7109 | AA8: =Z8*(1-Hypotheses!D14)+AA7 -> 2330.8996 | AB8: =AA8*(1-Hypotheses!D14)+AB7 -> 2560.9726 | AC8: =AB8*(1-Hypotheses!D14)+AC7 -> 2784.1434 | AD8: =AC8*(1-Hypotheses!D14)+AD7 -> 3000.6191 | AE8: =AD8*(1-Hypotheses!D14)+AE7 -> 3210.6005 | AF8: =AE8*(1-Hypotheses!D14)+AF7 -> 3414.2825 | AG8: =AF8*(1-Hypotheses!D14)+AG7 -> 3611.854 | AH8: =AG8*(1-Hypotheses!D14)+AH7 -> 3803.4984 | AI8: =AH8*(1-Hypotheses!D14)+AI7 -> 3989.3935 | AJ8: =AI8*(1-Hypotheses!D14)+AJ7 -> 4169.7117 | AK8: =AJ8*(1-Hypotheses!D14)+AK7 -> 4344.6203 | AL8: =AK8*(1-Hypotheses!D14)+AL7 -> 4514.2817
A10: Pro actifs (arrondi) | B10: =ROUND(B8,0) -> 0 | C10: =ROUND(C8,0) -> 33 | D10: =ROUND(D8,0) -> 66 | E10: =ROUND(E8,0) -> 97 | F10: =ROUND(F8,0) -> 144 | G10: =ROUND(G8,0) -> 190 | H10: =ROUND(H8,0) -> 234 | I10: =ROUND(I8,0) -> 294 | ... AL10: =ROUND(AL8,0) -> 4514
A12: Comptes Equipe | B12: 0 | C12: 0 | D12: 0 | E12: 0 | F12: =ROUND(F10*Hypotheses!D18,0) -> 22 | G12: =ROUND(G10*Hypotheses!D18,0) -> 29 | H12: =ROUND(H10*Hypotheses!D18,0) -> 35 | I12: =ROUND(I10*Hypotheses!D18,0) -> 44 | J12: =ROUND(J10*Hypotheses!D18,0) -> 53 | K12: =ROUND(K10*Hypotheses!D18,0) -> 61 | L12: =ROUND(L10*Hypotheses!D18,0) -> 69 | M12: =ROUND(M10*Hypotheses!D18,0) -> 77 | N12: =ROUND(N10*Hypotheses!D18,0) -> 85 | O12: =ROUND(O10*Hypotheses!D18,0) -> 107 | P12: =ROUND(P10*Hypotheses!D18,0) -> 129 | Q12: =ROUND(Q10*Hypotheses!D18,0) -> 150 | R12: =ROUND(R10*Hypotheses!D18,0) -> 171 | S12: =ROUND(S10*Hypotheses!D18,0) -> 191 | T12: =ROUND(T10*Hypotheses!D18,0) -> 210 | U12: =ROUND(U10*Hypotheses!D18,0) -> 229 | V12: =ROUND(V10*Hypotheses!D18,0) -> 247 | W12: =ROUND(W10*Hypotheses!D18,0) -> 264 | X12: =ROUND(X10*Hypotheses!D18,0) -> 281 | Y12: =ROUND(Y10*Hypotheses!D18,0) -> 298 | Z12: =ROUND(Z10*Hypotheses!D18,0) -> 314 | AA12: =ROUND(AA10*Hypotheses!D18,0) -> 350 | AB12: =ROUND(AB10*Hypotheses!D18,0) -> 384 | AC12: =ROUND(AC10*Hypotheses!D18,0) -> 418 | AD12: =ROUND(AD10*Hypotheses!D18,0) -> 450 | AE12: =ROUND(AE10*Hypotheses!D18,0) -> 482 | AF12: =ROUND(AF10*Hypotheses!D18,0) -> 512 | AG12: =ROUND(AG10*Hypotheses!D18,0) -> 542 | AH12: =ROUND(AH10*Hypotheses!D18,0) -> 570 | AI12: =ROUND(AI10*Hypotheses!D18,0) -> 598 | AJ12: =ROUND(AJ10*Hypotheses!D18,0) -> 626 | AK12: =ROUND(AK10*Hypotheses!D18,0) -> 652 | AL12: =ROUND(AL10*Hypotheses!D18,0) -> 677
